2024-09-07 13:13:49,820 [fail_agent_wrapper] ERROR: 
Traceback (most recent call last):
  File "/home/anushac/Documents/projects/Bomberman_MLE/agents.py", line 248, in process_event
    event_result = getattr(module, event_name)(self.fake_self, *event_args)
  File "/home/anushac/Documents/projects/Bomberman_MLE/agent_code/fail_agent/callbacks.py", line 9, in act
    raise ValueError()
ValueError
